Workbook
Name Abertas: Painel!$B$3
Name EmAndamento: Painel!$B$4
Name Fechadas: Painel!$B$5
Name Criticas: Painel!$B$7
Name Atrasadas: Painel!$B$8
Name PercentualAtraso: Painel!$B$9
Name PorUnidade: Painel!$B$12:$B$51

Sheet LEIA-ME
A1: CONTROLE DE OCORRÊNCIAS — LEIA ANTES DE MEXER
A3: 1. NÃO ORDENE A TABELA SEM SELECIONAR TUDO.
A4: 2. NÃO MEXA NA COLUNA L.
A5: 3. NO FIM DO MÊS, ARQUIVE AS OCORRÊNCIAS FECHADAS NA ABA DE ARQUIVO.
A8: Arquivo de exemplo do livro Power Fx na Prática (Capítulo 0). Dados fictícios: pessoas e unidades inventadas.

Sheet Ocorrencias
A1: NumeroOS | B1: Titulo | C1: Descricao | D1: Local | E1: Prioridade | F1: Responsavel | G1: Status | H1: DataAbertura | I1: Prazo | J1: Atrasada | K1: Supervisor | L1: NÃO MEXER
A2: OS-0140 | B2: Pintura descascada na estrutura E-23 | C2: Estrutura metálica E-23 com pontos de corrosão sob a pintura. | D2: Almoxarifado Central | E2: Média | F2: Daniela Pires | G2: Em Andamento | H2: 44991.694 | I2: =IF(Ocorrencias[[#This Row],[Prioridade]]="Crítica",Ocorrencias[[#This Row],[DataAbertura]]+1,IF(Ocorrencias[[#This Row],[Prioridade]]="Alta",Ocorrencias[[#This Row],[DataAbertura]]+3,Ocorrencias[[#This Row],[DataAbertura]]+10)) | J2: =IF(AND(Ocorrencias[[#This Row],[Status]]<>"Fechada",TODAY()>Ocorrencias[[#This Row],[Prazo]]),"SIM","") | K2: =IFERROR(VLOOKUP(Ocorrencias[[#This Row],[Local]],Unidades!A:B,2,FALSE),"") | L2: =IF(Ocorrencias[[#This Row],[Status]]="Fechada","",TODAY()-Ocorrencias[[#This Row],[DataAbertura]])
A3: OS-0177 | B3: Pintura descascada na estrutura G-17 | C3: Estrutura metálica G-17 com pontos de corrosão sob a pintura. | D3: Subestação Oeste | E3: Baixa | F3: Flávio Gusmão | G3: aberta | H3: 45012.361 | I3: =IF(Ocorrencias[[#This Row],[Prioridade]]="Crítica",Ocorrencias[[#This Row],[DataAbertura]]+1,IF(Ocorrencias[[#This Row],[Prioridade]]="Alta",Ocorrencias[[#This Row],[DataAbertura]]+3,Ocorrencias[[#This Row],[DataAbertura]]+10)) | J3: =IF(AND(Ocorrencias[[#This Row],[Status]]<>"Fechada",TODAY()>Ocorrencias[[#This Row],[Prazo]]),"SIM","") | K3: =IFERROR(VLOOKUP(Ocorrencias[[#This Row],[Local]],Unidades!A:B,2,FALSE),"") | L3: =IF(Ocorrencias[[#This Row],[Status]]="Fechada","",TODAY()-Ocorrencias[[#This Row],[DataAbertura]])
A4: OS-0214 | B4: Falha de comunicação no CLP P-34 | C4: CLP P-34 perde comunicação com o supervisório em intervalos irregulares. | D4: Booster Morada do Sol | E4: Baixa | F4: Simone Carvalho | G4: Aberto | H4: 45033.465 | I4: =IF(Ocorrencias[[#This Row],[Prioridade]]="Crítica",Ocorrencias[[#This Row],[DataAbertura]]+1,IF(Ocorrencias[[#This Row],[Prioridade]]="Alta",Ocorrencias[[#This Row],[DataAbertura]]+3,Ocorrencias[[#This Row],[DataAbertura]]+10)) | J4: =IF(AND(Ocorrencias[[#This Row],[Status]]<>"Fechada",TODAY()>Ocorrencias[[#This Row],[Prazo]]),"SIM","") | K4: =IFERROR(VLOOKUP(Ocorrencias[[#This Row],[Local]],Unidades!A:B,2,FALSE),"") | L4: =IF(Ocorrencias[[#This Row],[Status]]="Fechada","",TODAY()-Ocorrencias[[#This Row],[DataAbertura]])
A5: OS-0251 | B5: Medidor de vazão A-06 com leitura instável | C5: Medidor de vazão A-06 oscila sem variação de processo. | D5: Subestação Leste | E5: Média | F5: Érica Andrade | G5: Em Andamento | H5: 45054.368 | I5: =IF(Ocorrencias[[#This Row],[Prioridade]]="Crítica",Ocorrencias[[#This Row],[DataAbertura]]+1,IF(Ocorrencias[[#This Row],[Prioridade]]="Alta",Ocorrencias[[#This Row],[DataAbertura]]+3,Ocorrencias[[#This Row],[DataAbertura]]+10)) | J5: =IF(AND(Ocorrencias[[#This Row],[Status]]<>"Fechada",TODAY()>Ocorrencias[[#This Row],[Prazo]]),"SIM","") | K5: =IFERROR(VLOOKUP(Ocorrencias[[#This Row],[Local]],Unidades!A:B,2,FALSE),"") | L5: =IF(Ocorrencias[[#This Row],[Status]]="Fechada","",TODAY()-Ocorrencias[[#This Row],[DataAbertura]])
A6: OS-0288 | B6: Exaustor C-25 parado | C6: Exaustor C-25 não parte. Fusível íntegro. | D6: Base Operacional Norte | E6: Baixa | F6: Flávio Gusmão | G6: Aberto | H6: 45075.701 | I6: =IF(Ocorrencias[[#This Row],[Prioridade]]="Crítica",Ocorrencias[[#This Row],[DataAbertura]]+1,IF(Ocorrencias[[#This Row],[Prioridade]]="Alta",Ocorrencias[[#This Row],[DataAbertura]]+3,Ocorrencias[[#This Row],[DataAbertura]]+10)) | J6: =IF(AND(Ocorrencias[[#This Row],[Status]]<>"Fechada",TODAY()>Ocorrencias[[#This Row],[Prazo]]),"SIM","") | K6: =IFERROR(VLOOKUP(Ocorrencias[[#This Row],[Local]],Unidades!A:B,2,FALSE),"") | L6: =IF(Ocorrencias[[#This Row],[Status]]="Fechada","",TODAY()-Ocorrencias[[#This Row],[DataAbertura]])
A7: OS-0325 | B7: Ar-condicionado da sala M-35 sem refrigerar | C7: Ar-condicionado da sala de painéis M-35 ligado sem refrigerar. | D7: Estação de Bombeamento Vila Nova | E7: Crítica | F7: Igor Fonseca | G7: Aberto | H7: 45096.41 | I7: =IF(Ocorrencias[[#This Row],[Prioridade]]="Crítica",Ocorrencias[[#This Row],[DataAbertura]]+1,IF(Ocorrencias[[#This Row],[Prioridade]]="Alta",Ocorrencias[[#This Row],[DataAbertura]]+3,Ocorrencias[[#This Row],[DataAbertura]]+10)) | J7: =IF(AND(Ocorrencias[[#This Row],[Status]]<>"Fechada",TODAY()>Ocorrencias[[#This Row],[Prazo]]),"SIM","") | K7: =IFERROR(VLOOKUP(Ocorrencias[[#This Row],[Local]],Unidades!A:B,2,FALSE),"") | L7: =IF(Ocorrencias[[#This Row],[Status]]="Fechada","",TODAY()-Ocorrencias[[#This Row],[DataAbertura]])
A8: OS-0362 | B8: Vazamento na bomba C-26 | C8: Vazamento pelo selo mecânico da bomba C-26. Piso molhado ao redor da base. | D8: Adutora Tronco Norte | E8: Alta | F8: Rafael Torres | G8: Aberto | H8: 45117.729 | I8: =IF(Ocorrencias[[#This Row],[Prioridade]]="Crítica",Ocorrencias[[#This Row],[DataAbertura]]+1,IF(Ocorrencias[[#This Row],[Prioridade]]="Alta",Ocorrencias[[#This Row],[DataAbertura]]+3,Ocorrencias[[#This Row],[DataAbertura]]+10)) | J8: =IF(AND(Ocorrencias[[#This Row],[Status]]<>"Fechada",TODAY()>Ocorrencias[[#This Row],[Prazo]]),"SIM","") | K8: =IFERROR(VLOOKUP(Ocorrencias[[#This Row],[Local]],Unidades!A:B,2,FALSE),"") | L8: =IF(Ocorrencias[[#This Row],[Status]]="Fechada","",TODAY()-Ocorrencias[[#This Row],[DataAbertura]])
A9: OS-0399 | B9: Vazamento na bomba A-05 | C9: Vazamento pelo selo mecânico da bomba A-05. Piso molhado ao redor da base. | D9: Captação Lagoa Seca | E9: Baixa | F9: Wesley Cardoso | G9: aberta | H9: 45138.632 | I9: =IF(Ocorrencias[[#This Row],[Prioridade]]="Crítica",Ocorrencias[[#This Row],[DataAbertura]]+1,IF(Ocorrencias[[#This Row],[Prioridade]]="Alta",Ocorrencias[[#This Row],[DataAbertura]]+3,Ocorrencias[[#This Row],[DataAbertura]]+10)) | J9: =IF(AND(Ocorrencias[[#This Row],[Status]]<>"Fechada",TODAY()>Ocorrencias[[#This Row],[Prazo]]),"SIM","") | K9: =IFERROR(VLOOKUP(Ocorrencias[[#This Row],[Local]],Unidades!A:B,2,FALSE),"") | L9: =IF(Ocorrencias[[#This Row],[Status]]="Fechada","",TODAY()-Ocorrencias[[#This Row],[DataAbertura]])
A10: OS-0436 | B10: Lâmpada queimada na área F-31 | C10: Iluminação da área F-31 sem funcionar. Reposição de lâmpada e conferência do reator. | D10: Usina Fotovoltaica Planalto | E10: Alta | F10: Flávio Gusmão | G10: aberta | H10: 45159.632 | I10: =IF(Ocorrencias[[#This Row],[Prioridade]]="Crítica",Ocorrencias[[#This Row],[DataAbertura]]+1,IF(Ocorrencias[[#This Row],[Prioridade]]="Alta",Ocorrencias[[#This Row],[DataAbertura]]+3,Ocorrencias[[#This Row],[DataAbertura]]+10)) | J10: =IF(AND(Ocorrencias[[#This Row],[Status]]<>"Fechada",TODAY()>Ocorrencias[[#This Row],[Prazo]]),"SIM","") | K10: =IFERROR(VLOOKUP(Ocorrencias[[#This Row],[Local]],Unidades!A:B,2,FALSE),"") | L10: =IF(Ocorrencias[[#This Row],[Status]]="Fechada","",TODAY()-Ocorrencias[[#This Row],[DataAbertura]])
A11: OS-0473 | B11: Infiltração na parede da casa de bombas H-16 | C11: Mancha de umidade crescente na parede da casa de bombas H-16. | D11: Base Operacional Litoral | E11: Média | F11: Cíntia Freitas | G11: Em Andamento | H11: 45180.41 | I11: =IF(Ocorrencias[[#This Row],[Prioridade]]="Crítica",Ocorrencias[[#This Row],[DataAbertura]]+1,IF(Ocorrencias[[#This Row],[Prioridade]]="Alta",Ocorrencias[[#This Row],[DataAbertura]]+3,Ocorrencias[[#This Row],[DataAbertura]]+10)) | J11: =IF(AND(Ocorrencias[[#This Row],[Status]]<>"Fechada",TODAY()>Ocorrencias[[#This Row],[Prazo]]),"SIM","") | K11: =IFERROR(VLOOKUP(Ocorrencias[[#This Row],[Local]],Unidades!A:B,2,FALSE),"") | L11: =IF(Ocorrencias[[#This Row],[Status]]="Fechada","",TODAY()-Ocorrencias[[#This Row],[DataAbertura]])
A12: OS-0510 | B12: Ruído anormal no motor M-16 | C12: Ruído intermitente no motor M-16 durante a partida. Temperatura normal ao toque. | D12: Reservatório Santa Luzia | E12: Média | F12: Heloísa Barreto | G12: Aberto | H12: 45201.66 | I12: =IF(Ocorrencias[[#This Row],[Prioridade]]="Crítica",Ocorrencias[[#This Row],[DataAbertura]]+1,IF(Ocorrencias[[#This Row],[Prioridade]]="Alta",Ocorrencias[[#This Row],[DataAbertura]]+3,Ocorrencias[[#This Row],[DataAbertura]]+10)) | J12: =IF(AND(Ocorrencias[[#This Row],[Status]]<>"Fechada",TODAY()>Ocorrencias[[#This Row],[Prazo]]),"SIM","") | K12: =IFERROR(VLOOKUP(Ocorrencias[[#This Row],[Local]],Unidades!A:B,2,FALSE),"") | L12: =IF(Ocorrencias[[#This Row],[Status]]="Fechada","",TODAY()-Ocorrencias[[#This Row],[DataAbertura]])
A13: OS-0547 | B13: Exaustor M-38 parado | C13: Exaustor M-38 não parte. Fusível íntegro. | D13: Adutora Tronco Norte | E13: Média | F13: Hugo Albuquerque | G13: Aberto | H13: 45222.66 | I13: =IF(Ocorrencias[[#This Row],[Prioridade]]="Crítica",Ocorrencias[[#This Row],[DataAbertura]]+1,IF(Ocorrencias[[#This Row],[Prioridade]]="Alta",Ocorrencias[[#This Row],[DataAbertura]]+3,Ocorrencias[[#This Row],[DataAbertura]]+10)) | J13: =IF(AND(Ocorrencias[[#This Row],[Status]]<>"Fechada",TODAY()>Ocorrencias[[#This Row],[Prazo]]),"SIM","") | K13: =IFERROR(VLOOKUP(Ocorrencias[[#This Row],[Local]],Unidades!A:B,2,FALSE),"") | L13: =IF(Ocorrencias[[#This Row],[Status]]="Fechada","",TODAY()-Ocorrencias[[#This Row],[DataAbertura]])
... A50: OS-2713 | B50: Calha entupida no prédio T-04 | C50: Calha do prédio T-04 transbordando em dia de chuva. | D50: Usina Fotovoltaica Planalto | E50: Média | F50: Ingrid Queiroz | G50: Fechada | H50: 46036.858 | I50: =IF(Ocorrencias[[#This Row],[Prioridade]]="Crítica",Ocorrencias[[#This Row],[DataAbertura]]+1,IF(Ocorrencias[[#This Row],[Prioridade]]="Alta",Ocorrencias[[#This Row],[DataAbertura]]+3,Ocorrencias[[#This Row],[DataAbertura]]+10)) | J50: =IF(AND(Ocorrencias[[#This Row],[Status]]<>"Fechada",TODAY()>Ocorrencias[[#This Row],[Prazo]]),"SIM","") | K50: =IFERROR(VLOOKUP(Ocorrencias[[#This Row],[Local]],Unidades!A:B,2,FALSE),"") | L50: =IF(Ocorrencias[[#This Row],[Status]]="Fechada","",TODAY()-Ocorrencias[[#This Row],[DataAbertura]])
A51: OS-2714 | B51: Troca de filtro do compressor P-20 | C51: Filtro de ar do compressor P-20 saturado. Substituição preventiva. | D51: ETE Rio Claro | E51: Baixa | G51: Fechada | H51: 46037.664 | I51: =IF(Ocorrencias[[#This Row],[Prioridade]]="Crítica",Ocorrencias[[#This Row],[DataAbertura]]+1,IF(Ocorrencias[[#This Row],[Prioridade]]="Alta",Ocorrencias[[#This Row],[DataAbertura]]+3,Ocorrencias[[#This Row],[DataAbertura]]+10)) | J51: =IF(AND(Ocorrencias[[#This Row],[Status]]<>"Fechada",TODAY()>Ocorrencias[[#This Row],[Prazo]]),"SIM","") | K51: =IFERROR(VLOOKUP(Ocorrencias[[#This Row],[Local]],Unidades!A:B,2,FALSE),"") | L51: =IF(Ocorrencias[[#This Row],[Status]]="Fechada","",TODAY()-Ocorrencias[[#This Row],[DataAbertura]])
A52: OS-2715 | B52: Tomada sem energia na sala F-40 | C52: Tomada de serviço da sala F-40 sem tensão. | D52: Base Operacional Sul | E52: Média | F52: Yara Medeiros | G52: Fechada | H52: 46038.45 | I52: =IF(Ocorrencias[[#This Row],[Prioridade]]="Crítica",Ocorrencias[[#This Row],[DataAbertura]]+1,IF(Ocorrencias[[#This Row],[Prioridade]]="Alta",Ocorrencias[[#This Row],[DataAbertura]]+3,Ocorrencias[[#This Row],[DataAbertura]]+10)) | J52: =IF(AND(Ocorrencias[[#This Row],[Status]]<>"Fechada",TODAY()>Ocorrencias[[#This Row],[Prazo]]),"SIM","") | K52: =IFERROR(VLOOKUP(Ocorrencias[[#This Row],[Local]],Unidades!A:B,2,FALSE),"") | L52: =IF(Ocorrencias[[#This Row],[Status]]="Fechada","",TODAY()-Ocorrencias[[#This Row],[DataAbertura]])
A53: OS-2716 | B53: Correia do ventilador P-15 desgastada | C53: Correia do ventilador P-15 com trincas visíveis e folga excessiva. | D53: Adutora Tronco Norte | E53: Crítica | F53: Aline Rocha | G53: Fechada | I53: =IF(Ocorrencias[[#This Row],[Prioridade]]="Crítica",Ocorrencias[[#This Row],[DataAbertura]]+1,IF(Ocorrencias[[#This Row],[Prioridade]]="Alta",Ocorrencias[[#This Row],[DataAbertura]]+3,Ocorrencias[[#This Row],[DataAbertura]]+10)) | J53: =IF(AND(Ocorrencias[[#This Row],[Status]]<>"Fechada",TODAY()>Ocorrencias[[#This Row],[Prazo]]),"SIM","") | K53: =IFERROR(VLOOKUP(Ocorrencias[[#This Row],[Local]],Unidades!A:B,2,FALSE),"") | L53: =IF(Ocorrencias[[#This Row],[Status]]="Fechada","",TODAY()-Ocorrencias[[#This Row],[DataAbertura]])
A54: OS-2717 | B54: Ar-condicionado da sala G-16 sem refrigerar | C54: Ar-condicionado da sala de painéis G-16 ligado sem refrigerar. | D54: Estação Elevatória Oeste | E54: Média | F54: Beatriz Farias | G54: Fechada | H54: 46040.006 | I54: =IF(Ocorrencias[[#This Row],[Prioridade]]="Crítica",Ocorrencias[[#This Row],[DataAbertura]]+1,IF(Ocorrencias[[#This Row],[Prioridade]]="Alta",Ocorrencias[[#This Row],[DataAbertura]]+3,Ocorrencias[[#This Row],[DataAbertura]]+10)) | J54: =IF(AND(Ocorrencias[[#This Row],[Status]]<>"Fechada",TODAY()>Ocorrencias[[#This Row],[Prazo]]),"SIM","") | K54: =IFERROR(VLOOKUP(Ocorrencias[[#This Row],[Local]],Unidades!A:B,2,FALSE),"") | L54: =IF(Ocorrencias[[#This Row],[Status]]="Fechada","",TODAY()-Ocorrencias[[#This Row],[DataAbertura]])
A55: OS-2718 | B55: Disjuntor desarmando no painel E-14 | C55: Disjuntor do painel E-14 desarmou três vezes no turno. Carga dentro do nominal. | D55: Almoxarifado Central | E55: Alta | F55: Glória Sampaio | G55: Fechada | H55: 46040.84 | I55: =IF(Ocorrencias[[#This Row],[Prioridade]]="Crítica",Ocorrencias[[#This Row],[DataAbertura]]+1,IF(Ocorrencias[[#This Row],[Prioridade]]="Alta",Ocorrencias[[#This Row],[DataAbertura]]+3,Ocorrencias[[#This Row],[DataAbertura]]+10)) | J55: =IF(AND(Ocorrencias[[#This Row],[Status]]<>"Fechada",TODAY()>Ocorrencias[[#This Row],[Prazo]]),"SIM","") | K55: =IFERROR(VLOOKUP(Ocorrencias[[#This Row],[Local]],Unidades!A:B,2,FALSE),"") | L55: =IF(Ocorrencias[[#This Row],[Status]]="Fechada","",TODAY()-Ocorrencias[[#This Row],[DataAbertura]])
A56: OS-2719 | B56: Sensor de nível sem leitura no tanque H-33 | C56: Supervisório mostra leitura congelada do sensor de nível do tanque H-33. | D56: Subestação Norte | E56: Alta | F56: Fernanda Quintela | G56: Fechada | H56: 46041.619 | I56: =IF(Ocorrencias[[#This Row],[Prioridade]]="Crítica",Ocorrencias[[#This Row],[DataAbertura]]+1,IF(Ocorrencias[[#This Row],[Prioridade]]="Alta",Ocorrencias[[#This Row],[DataAbertura]]+3,Ocorrencias[[#This Row],[DataAbertura]]+10)) | J56: =IF(AND(Ocorrencias[[#This Row],[Status]]<>"Fechada",TODAY()>Ocorrencias[[#This Row],[Prazo]]),"SIM","") | K56: =IFERROR(VLOOKUP(Ocorrencias[[#This Row],[Local]],Unidades!A:B,2,FALSE),"") | L56: =IF(Ocorrencias[[#This Row],[Status]]="Fechada","",TODAY()-Ocorrencias[[#This Row],[DataAbertura]])
A57: OS-2720 | B57: Disjuntor desarmando no painel C-14 | C57: Disjuntor do painel C-14 desarmou três vezes no turno. Carga dentro do nominal. | D57: Reservatório Santa Luzia | E57: Média | F57: Yara Medeiros | G57: Fechada | H57: 46042.39 | I57: =IF(Ocorrencias[[#This Row],[Prioridade]]="Crítica",Ocorrencias[[#This Row],[DataAbertura]]+1,IF(Ocorrencias[[#This Row],[Prioridade]]="Alta",Ocorrencias[[#This Row],[DataAbertura]]+3,Ocorrencias[[#This Row],[DataAbertura]]+10)) | J57: =IF(AND(Ocorrencias[[#This Row],[Status]]<>"Fechada",TODAY()>Ocorrencias[[#This Row],[Prazo]]),"SIM","") | K57: =IFERROR(VLOOKUP(Ocorrencias[[#This Row],[Local]],Unidades!A:B,2,FALSE),"") | L57: =IF(Ocorrencias[[#This Row],[Status]]="Fechada","",TODAY()-Ocorrencias[[#This Row],[DataAbertura]])
A58: OS-2721 | B58: Tomada sem energia na sala T-07 | C58: Tomada de serviço da sala T-07 sem tensão. | D58: Estação Elevatória Leste | E58: Média | F58: Alex Nogueira | G58: Fechada | I58: =IF(Ocorrencias[[#This Row],[Prioridade]]="Crítica",Ocorrencias[[#This Row],[DataAbertura]]+1,IF(Ocorrencias[[#This Row],[Prioridade]]="Alta",Ocorrencias[[#This Row],[DataAbertura]]+3,Ocorrencias[[#This Row],[DataAbertura]]+10)) | J58: =IF(AND(Ocorrencias[[#This Row],[Status]]<>"Fechada",TODAY()>Ocorrencias[[#This Row],[Prazo]]),"SIM","") | K58: =IFERROR(VLOOKUP(Ocorrencias[[#This Row],[Local]],Unidades!A:B,2,FALSE),"") | L58: =IF(Ocorrencias[[#This Row],[Status]]="Fechada","",TODAY()-Ocorrencias[[#This Row],[DataAbertura]])
A59: OS-2722 | B59: Disjuntor desarmando no painel C-22 | C59: Disjuntor do painel C-22 desarmou três vezes no turno. Carga dentro do nominal. | D59: Reservatório Industrial | E59: Média | F59: Cíntia Freitas | G59: Fechada | H59: 46043.974 | I59: =IF(Ocorrencias[[#This Row],[Prioridade]]="Crítica",Ocorrencias[[#This Row],[DataAbertura]]+1,IF(Ocorrencias[[#This Row],[Prioridade]]="Alta",Ocorrencias[[#This Row],[DataAbertura]]+3,Ocorrencias[[#This Row],[DataAbertura]]+10)) | J59: =IF(AND(Ocorrencias[[#This Row],[Status]]<>"Fechada",TODAY()>Ocorrencias[[#This Row],[Prazo]]),"SIM","") | K59: =IFERROR(VLOOKUP(Ocorrencias[[#This Row],[Local]],Unidades!A:B,2,FALSE),"") | L59: =IF(Ocorrencias[[#This Row],[Status]]="Fechada","",TODAY()-Ocorrencias[[#This Row],[DataAbertura]])
A60: OS-2723 | B60: Disjuntor desarmando no painel T-07 | C60: Disjuntor do painel T-07 desarmou três vezes no turno. Carga dentro do nominal. | D60: ETA Ribeirão Fundo | E60: Baixa | F60: Murilo Paiva | G60: Em andamento | H60: 46044.766 | I60: =IF(Ocorrencias[[#This Row],[Prioridade]]="Crítica",Ocorrencias[[#This Row],[DataAbertura]]+1,IF(Ocorrencias[[#This Row],[Prioridade]]="Alta",Ocorrencias[[#This Row],[DataAbertura]]+3,Ocorrencias[[#This Row],[DataAbertura]]+10)) | J60: =IF(AND(Ocorrencias[[#This Row],[Status]]<>"Fechada",TODAY()>Ocorrencias[[#This Row],[Prazo]]),"SIM","") | K60: =IFERROR(VLOOKUP(Ocorrencias[[#This Row],[Local]],Unidades!A:B,2,FALSE),"") | L60: =IF(Ocorrencias[[#This Row],[Status]]="Fechada","",TODAY()-Ocorrencias[[#This Row],[DataAbertura]])
A61: OS-2724 | B61: Calha entupida no prédio G-39 | C61: Calha do prédio G-39 transbordando em dia de chuva. | D61: Subestação Oeste | E61: Alta | F61: Priscila Guedes | G61: Fechada | H61: 46045.585 | I61: =IF(Ocorrencias[[#This Row],[Prioridade]]="Crítica",Ocorrencias[[#This Row],[DataAbertura]]+1,IF(Ocorrencias[[#This Row],[Prioridade]]="Alta",Ocorrencias[[#This Row],[DataAbertura]]+3,Ocorrencias[[#This Row],[DataAbertura]]+10)) | J61: =IF(AND(Ocorrencias[[#This Row],[Status]]<>"Fechada",TODAY()>Ocorrencias[[#This Row],[Prazo]]),"SIM","") | K61: =IFERROR(VLOOKUP(Ocorrencias[[#This Row],[Local]],Unidades!A:B,2,FALSE),"") | L61: =IF(Ocorrencias[[#This Row],[Status]]="Fechada","",TODAY()-Ocorrencias[[#This Row],[DataAbertura]])
A62: OS-2725 | B62: Lâmpada queimada na área M-30 | C62: Iluminação da área M-30 sem funcionar. Reposição de lâmpada e conferência do reator. | D62: Estação de Bombeamento Três Pontes | E62: Baixa | F62: Murilo Paiva | G62: Aberta | H62: 46046.35 | I62: =IF(Ocorrencias[[#This Row],[Prioridade]]="Crítica",Ocorrencias[[#This Row],[DataAbertura]]+1,IF(Ocorrencias[[#This Row],[Prioridade]]="Alta",Ocorrencias[[#This Row],[DataAbertura]]+3,Ocorrencias[[#This Row],[DataAbertura]]+10)) | J62: =IF(AND(Ocorrencias[[#This Row],[Status]]<>"Fechada",TODAY()>Ocorrencias[[#This Row],[Prazo]]),"SIM","") | K62: =IFERROR(VLOOKUP(Ocorrencias[[#This Row],[Local]],Unidades!A:B,2,FALSE),"") | L62: =IF(Ocorrencias[[#This Row],[Status]]="Fechada","",TODAY()-Ocorrencias[[#This Row],[DataAbertura]])
A63: OS-2726 | B63: Vazamento de óleo no redutor D-06 | C63: Gotejamento de óleo no redutor D-06. Nível ainda dentro da faixa. | D63: Reservatório Industrial | E63: Crítica | F63: Eduardo Salles | G63: Fechada | H63: 46047.184 | I63: =IF(Ocorrencias[[#This Row],[Prioridade]]="Crítica",Ocorrencias[[#This Row],[DataAbertura]]+1,IF(Ocorrencias[[#This Row],[Prioridade]]="Alta",Ocorrencias[[#This Row],[DataAbertura]]+3,Ocorrencias[[#This Row],[DataAbertura]]+10)) | J63: =IF(AND(Ocorrencias[[#This Row],[Status]]<>"Fechada",TODAY()>Ocorrencias[[#This Row],[Prazo]]),"SIM","") | K63: =IFERROR(VLOOKUP(Ocorrencias[[#This Row],[Local]],Unidades!A:B,2,FALSE),"") | L63: =IF(Ocorrencias[[#This Row],[Status]]="Fechada","",TODAY()-Ocorrencias[[#This Row],[DataAbertura]])
A64: OS-2727 | B64: Bomba dosadora M-04 sem recalque | C64: Bomba dosadora M-04 liga mas não dosa. Mangueira sem obstrução aparente. | D64: Estação Elevatória Leste | E64: Média | F64: Gabriel Matos | G64: Fechada | H64: 46047.963 | I64: =IF(Ocorrencias[[#This Row],[Prioridade]]="Crítica",Ocorrencias[[#This Row],[DataAbertura]]+1,IF(Ocorrencias[[#This Row],[Prioridade]]="Alta",Ocorrencias[[#This Row],[DataAbertura]]+3,Ocorrencias[[#This Row],[DataAbertura]]+10)) | J64: =IF(AND(Ocorrencias[[#This Row],[Status]]<>"Fechada",TODAY()>Ocorrencias[[#This Row],[Prazo]]),"SIM","") | K64: =IFERROR(VLOOKUP(Ocorrencias[[#This Row],[Local]],Unidades!A:B,2,FALSE),"") | L64: =IF(Ocorrencias[[#This Row],[Status]]="Fechada","",TODAY()-Ocorrencias[[#This Row],[DataAbertura]])
A65: OS-2728 | B65: Ruído anormal no motor H-12 | C65: Ruído intermitente no motor H-12 durante a partida. Temperatura normal ao toque. | D65: Subestação Leste | E65: Média | F65: Lívia Montenegro | G65: Fechada | H65: 46048.742 | I65: =IF(Ocorrencias[[#This Row],[Prioridade]]="Crítica",Ocorrencias[[#This Row],[DataAbertura]]+1,IF(Ocorrencias[[#This Row],[Prioridade]]="Alta",Ocorrencias[[#This Row],[DataAbertura]]+3,Ocorrencias[[#This Row],[DataAbertura]]+10)) | J65: =IF(AND(Ocorrencias[[#This Row],[Status]]<>"Fechada",TODAY()>Ocorrencias[[#This Row],[Prazo]]),"SIM","") | K65: =IFERROR(VLOOKUP(Ocorrencias[[#This Row],[Local]],Unidades!A:B,2,FALSE),"") | L65: =IF(Ocorrencias[[#This Row],[Status]]="Fechada","",TODAY()-Ocorrencias[[#This Row],[DataAbertura]])
A66: OS-2729 | B66: Tomada sem energia na sala E-28 | C66: Tomada de serviço da sala E-28 sem tensão. | D66: Booster Parque das Águas | E66: Alta | F66: Alex Nogueira | G66: Fechada | H66: 46049.567 | I66: =IF(Ocorrencias[[#This Row],[Prioridade]]="Crítica",Ocorrencias[[#This Row],[DataAbertura]]+1,IF(Ocorrencias[[#This Row],[Prioridade]]="Alta",Ocorrencias[[#This Row],[DataAbertura]]+3,Ocorrencias[[#This Row],[DataAbertura]]+10)) | J66: =IF(AND(Ocorrencias[[#This Row],[Status]]<>"Fechada",TODAY()>Ocorrencias[[#This Row],[Prazo]]),"SIM","") | K66: =IFERROR(VLOOKUP(Ocorrencias[[#This Row],[Local]],Unidades!A:B,2,FALSE),"") | L66: =IF(Ocorrencias[[#This Row],[Status]]="Fechada","",TODAY()-Ocorrencias[[#This Row],[DataAbertura]])
A67: OS-2730 | B67: Lâmpada queimada na área R-39 | C67: Iluminação da área R-39 sem funcionar. Reposição de lâmpada e conferência do reator. | D67: ETE Rio Claro | E67: Baixa | F67: Danilo Peixoto | G67: Fechada | H67: 46050.335 | I67: =IF(Ocorrencias[[#This Row],[Prioridade]]="Crítica",Ocorrencias[[#This Row],[DataAbertura]]+1,IF(Ocorrencias[[#This Row],[Prioridade]]="Alta",Ocorrencias[[#This Row],[DataAbertura]]+3,Ocorrencias[[#This Row],[DataAbertura]]+10)) | J67: =IF(AND(Ocorrencias[[#This Row],[Status]]<>"Fechada",TODAY()>Ocorrencias[[#This Row],[Prazo]]),"SIM","") | K67: =IFERROR(VLOOKUP(Ocorrencias[[#This Row],[Local]],Unidades!A:B,2,FALSE),"") | L67: =IF(Ocorrencias[[#This Row],[Status]]="Fechada","",TODAY()-Ocorrencias[[#This Row],[DataAbertura]])
A68: OS-2731 | B68: Disjuntor desarmando no painel V-15 | C68: Disjuntor do painel V-15 desarmou três vezes no turno. Carga dentro do nominal. | D68: Pátio de Veículos | E68: Média | F68: Cíntia Freitas | G68: Fechada | H68: 46051.16 | I68: =IF(Ocorrencias[[#This Row],[Prioridade]]="Crítica",Ocorrencias[[#This Row],[DataAbertura]]+1,IF(Ocorrencias[[#This Row],[Prioridade]]="Alta",Ocorrencias[[#This Row],[DataAbertura]]+3,Ocorrencias[[#This Row],[DataAbertura]]+10)) | J68: =IF(AND(Ocorrencias[[#This Row],[Status]]<>"Fechada",TODAY()>Ocorrencias[[#This Row],[Prazo]]),"SIM","") | K68: =IFERROR(VLOOKUP(Ocorrencias[[#This Row],[Local]],Unidades!A:B,2,FALSE),"") | L68: =IF(Ocorrencias[[#This Row],[Status]]="Fechada","",TODAY()-Ocorrencias[[#This Row],[DataAbertura]])
A69: OS-2732 | B69: Aquecimento no mancal do motor R-40 | C69: Mancal do motor R-40 acima da temperatura usual na medição com termômetro infravermelho. | D69: Reservatório Alto da Colina | E69: Alta | F69: Úrsula Maia | G69: Fechada | H69: 46051.964 | I69: =IF(Ocorrencias[[#This Row],[Prioridade]]="Crítica",Ocorrencias[[#This Row],[DataAbertura]]+1,IF(Ocorrencias[[#This Row],[Prioridade]]="Alta",Ocorrencias[[#This Row],[DataAbertura]]+3,Ocorrencias[[#This Row],[DataAbertura]]+10)) | J69: =IF(AND(Ocorrencias[[#This Row],[Status]]<>"Fechada",TODAY()>Ocorrencias[[#This Row],[Prazo]]),"SIM","") | K69: =IFERROR(VLOOKUP(Ocorrencias[[#This Row],[Local]],Unidades!A:B,2,FALSE),"") | L69: =IF(Ocorrencias[[#This Row],[Status]]="Fechada","",TODAY()-Ocorrencias[[#This Row],[DataAbertura]])
A70: OS-2733 | B70: Infiltração na parede da casa de bombas V-39 | C70: Mancha de umidade crescente na parede da casa de bombas V-39. | D70: Adutora Tronco Norte | E70: Média | F70: Rafael Torres | G70: Fechada | H70: 46052.756 | I70: =IF(Ocorrencias[[#This Row],[Prioridade]]="Crítica",Ocorrencias[[#This Row],[DataAbertura]]+1,IF(Ocorrencias[[#This Row],[Prioridade]]="Alta",Ocorrencias[[#This Row],[DataAbertura]]+3,Ocorrencias[[#This Row],[DataAbertura]]+10)) | J70: =IF(AND(Ocorrencias[[#This Row],[Status]]<>"Fechada",TODAY()>Ocorrencias[[#This Row],[Prazo]]),"SIM","") | K70: =IFERROR(VLOOKUP(Ocorrencias[[#This Row],[Local]],Unidades!A:B,2,FALSE),"") | L70: =IF(Ocorrencias[[#This Row],[Status]]="Fechada","",TODAY()-Ocorrencias[[#This Row],[DataAbertura]])
... A72: OS-2735 | B72: Portão da área E-38 emperrado | C72: Portão de acesso da área E-38 exige força excessiva para abrir. | D72: Estação Elevatória Oeste | E72: Média | F72: Jonas Teles | G72: Fechada | H72: 46054.294 | I72: =IF(Ocorrencias[[#This Row],[Prioridade]]="Crítica",Ocorrencias[[#This Row],[DataAbertura]]+1,IF(Ocorrencias[[#This Row],[Prioridade]]="Alta",Ocorrencias[[#This Row],[DataAbertura]]+3,Ocorrencias[[#This Row],[DataAbertura]]+10)) | J72: =IF(AND(Ocorrencias[[#This Row],[Status]]<>"Fechada",TODAY()>Ocorrencias[[#This Row],[Prazo]]),"SIM","") | K72: =IFERROR(VLOOKUP(Ocorrencias[[#This Row],[Local]],Unidades!A:B,2,FALSE),"") | L72: =IF(Ocorrencias[[#This Row],[Status]]="Fechada","",TODAY()-Ocorrencias[[#This Row],[DataAbertura]])
A73: OS-2736 | B73: Medidor de vazão F-20 com leitura instável | C73: Medidor de vazão F-20 oscila sem variação de processo. | D73: Oficina Elétrica Central | E73: Alta | G73: Aberta | H73: 46055.101 | I73: =IF(Ocorrencias[[#This Row],[Prioridade]]="Crítica",Ocorrencias[[#This Row],[DataAbertura]]+1,IF(Ocorrencias[[#This Row],[Prioridade]]="Alta",Ocorrencias[[#This Row],[DataAbertura]]+3,Ocorrencias[[#This Row],[DataAbertura]]+10)) | J73: =IF(AND(Ocorrencias[[#This Row],[Status]]<>"Fechada",TODAY()>Ocorrencias[[#This Row],[Prazo]]),"SIM","") | K73: =IFERROR(VLOOKUP(Ocorrencias[[#This Row],[Local]],Unidades!A:B,2,FALSE),"") | L73: =IF(Ocorrencias[[#This Row],[Status]]="Fechada","",TODAY()-Ocorrencias[[#This Row],[DataAbertura]])
A74: OS-2737 | B74: Válvula R-39 não fecha por completo | C74: Válvula R-39 com passagem residual mesmo totalmente fechada. Possível desgaste da sede. | D74: Estação Elevatória Leste | E74: Média | F74: Heloísa Barreto | G74: Fechada | H74: 46055.928 | I74: =IF(Ocorrencias[[#This Row],[Prioridade]]="Crítica",Ocorrencias[[#This Row],[DataAbertura]]+1,IF(Ocorrencias[[#This Row],[Prioridade]]="Alta",Ocorrencias[[#This Row],[DataAbertura]]+3,Ocorrencias[[#This Row],[DataAbertura]]+10)) | J74: =IF(AND(Ocorrencias[[#This Row],[Status]]<>"Fechada",TODAY()>Ocorrencias[[#This Row],[Prazo]]),"SIM","") | K74: =IFERROR(VLOOKUP(Ocorrencias[[#This Row],[Local]],Unidades!A:B,2,FALSE),"") | L74: =IF(Ocorrencias[[#This Row],[Status]]="Fechada","",TODAY()-Ocorrencias[[#This Row],[DataAbertura]])
A75: OS-2738 | B75: Troca de filtro do compressor H-28 | C75: Filtro de ar do compressor H-28 saturado. Substituição preventiva. | D75: Almoxarifado Central | E75: Média | F75: Gabriel Matos | G75: Fechada | I75: =IF(Ocorrencias[[#This Row],[Prioridade]]="Crítica",Ocorrencias[[#This Row],[DataAbertura]]+1,IF(Ocorrencias[[#This Row],[Prioridade]]="Alta",Ocorrencias[[#This Row],[DataAbertura]]+3,Ocorrencias[[#This Row],[DataAbertura]]+10)) | J75: =IF(AND(Ocorrencias[[#This Row],[Status]]<>"Fechada",TODAY()>Ocorrencias[[#This Row],[Prazo]]),"SIM","") | K75: =IFERROR(VLOOKUP(Ocorrencias[[#This Row],[Local]],Unidades!A:B,2,FALSE),"") | L75: =IF(Ocorrencias[[#This Row],[Status]]="Fechada","",TODAY()-Ocorrencias[[#This Row],[DataAbertura]])
A76: OS-2739 | B76: Falha de comunicação no CLP H-29 | C76: CLP H-29 perde comunicação com o supervisório em intervalos irregulares. | D76: Oficina Mecânica Central | E76: Média | F76: Yara Medeiros | G76: Fechada | H76: 46057.486 | I76: =IF(Ocorrencias[[#This Row],[Prioridade]]="Crítica",Ocorrencias[[#This Row],[DataAbertura]]+1,IF(Ocorrencias[[#This Row],[Prioridade]]="Alta",Ocorrencias[[#This Row],[DataAbertura]]+3,Ocorrencias[[#This Row],[DataAbertura]]+10)) | J76: =IF(AND(Ocorrencias[[#This Row],[Status]]<>"Fechada",TODAY()>Ocorrencias[[#This Row],[Prazo]]),"SIM","") | K76: =IFERROR(VLOOKUP(Ocorrencias[[#This Row],[Local]],Unidades!A:B,2,FALSE),"") | L76: =IF(Ocorrencias[[#This Row],[Status]]="Fechada","",TODAY()-Ocorrencias[[#This Row],[DataAbertura]])
A77: OS-2740 | B77: Vazamento na bomba G-25 | C77: Vazamento pelo selo mecânico da bomba G-25. Piso molhado ao redor da base. | D77: ETA Central | E77: Baixa | F77: Glória Sampaio | G77: Fechada | H77: 46058.265 | I77: =IF(Ocorrencias[[#This Row],[Prioridade]]="Crítica",Ocorrencias[[#This Row],[DataAbertura]]+1,IF(Ocorrencias[[#This Row],[Prioridade]]="Alta",Ocorrencias[[#This Row],[DataAbertura]]+3,Ocorrencias[[#This Row],[DataAbertura]]+10)) | J77: =IF(AND(Ocorrencias[[#This Row],[Status]]<>"Fechada",TODAY()>Ocorrencias[[#This Row],[Prazo]]),"SIM","") | K77: =IFERROR(VLOOKUP(Ocorrencias[[#This Row],[Local]],Unidades!A:B,2,FALSE),"") | L77: =IF(Ocorrencias[[#This Row],[Status]]="Fechada","",TODAY()-Ocorrencias[[#This Row],[DataAbertura]])
...

Sheet Painel
A1: PAINEL DE OCORRÊNCIAS | B1: ="Atualizado em "&TEXT(DAY(TODAY()),"00")&"/"&TEXT(MONTH(TODAY()),"00")&"/"&YEAR(TODAY())
A3: Abertas | B3: =COUNTIF(Ocorrencias[Status],"Aberta")
A4: Em andamento | B4: =COUNTIF(Ocorrencias[Status],"Em andamento")
A5: Fechadas | B5: =COUNTIF(Ocorrencias[Status],"Fechada")
A7: Críticas em aberto | B7: =COUNTIFS(Ocorrencias!G2:G300,"Aberta",Ocorrencias!E2:E300,"Crítica")
A8: Atrasadas | B8: =COUNTIF(Ocorrencias[Atrasada],"SIM")
A9: Percentual de atraso | B9: =IFERROR(B8/(B3+B4),0)
A11: Abertas por unidade
A12: Subestação Norte | B12: =COUNTIFS(Ocorrencias[Local],A12,Ocorrencias[Status],"Aberta")
A13: Subestação Sul | B13: =COUNTIFS(Ocorrencias[Local],A13,Ocorrencias[Status],"Aberta")
A14: Subestação Leste | B14: =COUNTIFS(Ocorrencias[Local],A14,Ocorrencias[Status],"Aberta")
A15: Subestação Oeste | B15: =COUNTIFS(Ocorrencias[Local],A15,Ocorrencias[Status],"Aberta")
A16: Subestação Centro | B16: =COUNTIFS(Ocorrencias[Local],A16,Ocorrencias[Status],"Aberta")
A17: ETA Central | B17: =COUNTIFS(Ocorrencias[Local],A17,Ocorrencias[Status],"Aberta")
A18: ETA Serra Azul | B18: =COUNTIFS(Ocorrencias[Local],A18,Ocorrencias[Status],"Aberta")
A19: ETA Ribeirão Fundo | B19: =COUNTIFS(Ocorrencias[Local],A19,Ocorrencias[Status],"Aberta")
A20: ETE Vale do Sol | B20: =COUNTIFS(Ocorrencias[Local],A20,Ocorrencias[Status],"Aberta")
A21: ETE Rio Claro | B21: =COUNTIFS(Ocorrencias[Local],A21,Ocorrencias[Status],"Aberta")
A22: ETE Jardim Bela Vista | B22: =COUNTIFS(Ocorrencias[Local],A22,Ocorrencias[Status],"Aberta")
A23: Estação Elevatória Leste | B23: =COUNTIFS(Ocorrencias[Local],A23,Ocorrencias[Status],"Aberta")
... A51: Torre de Telecomunicação Morro Alto | B51: =COUNTIFS(Ocorrencias[Local],A51,Ocorrencias[Status],"Aberta")

Sheet Unidades
A1: Nome | B1: Supervisor
A2: Subestação Norte | B2: Adriana Campos
A3: Subestação Sul | B3: Adriana Campos
A4: Subestação Leste | B4: Bruno Teixeira
A5: Subestação Oeste | B5: Bruno Teixeira
A6: Subestação Centro | B6: Carla Menezes
A7: ETA Central | B7: Carla Menezes
A8: ETA Serra Azul | B8: Diego Fontana
A9: ETA Ribeirão Fundo | B9: Diego Fontana
A10: ETE Vale do Sol | B10: Elaine Prado
A11: ETE Rio Claro | B11: Elaine Prado
A12: ETE Jardim Bela Vista | B12: Fábio Rezende
... A41: Torre de Telecomunicação Morro Alto | B41: Tiago Moreira

Sheet Equipe
A1: Nome | B1: Funcao | C1: Area
A2: Adriana Campos | B2: Supervisor | C2: Operação
A3: Bruno Teixeira | B3: Supervisor | C3: Operação
A4: Carla Menezes | B4: Supervisor | C4: Operação
A5: Diego Fontana | B5: Supervisor | C5: Operação
A6: Elaine Prado | B6: Supervisor | C6: Operação
A7: Fábio Rezende | B7: Supervisor | C7: Operação
A8: Gisele Arantes | B8: Supervisor | C8: Operação
A9: Henrique Vasconcelos | B9: Supervisor | C9: Operação
A10: Isabela Moura | B10: Supervisor | C10: Operação
A11: João Batista Lemos | B11: Supervisor | C11: Operação
A12: Karina Duarte | B12: Supervisor | C12: Operação
... A57: Murilo Paiva | B57: Técnico | C57: Mecânica

Sheet Listas
A1: Status | B1: Prioridade
A2: Aberta | B2: Crítica
A3: Em andamento | B3: Alta
A4: Fechada | B4: Média
B5: Baixa

Sheet Arquivo_2025
A1: NumeroOS | B1: Titulo | C1: Descricao | D1: Local | E1: Prioridade | F1: Responsavel | G1: Status | H1: DataAbertura
A2: OS-1500 | B2: Ruído anormal no motor A-16 | C2: Ruído intermitente no motor A-16 durante a partida. Temperatura normal ao toque. | D2: Captação Lagoa Seca | E2: Média | F2: Simone Carvalho | G2: Fechada | H2: 45659.298
A3: OS-1501 | B3: Vazamento na bomba E-20 | C3: Vazamento pelo selo mecânico da bomba E-20. Piso molhado ao redor da base. | D3: Subestação Leste | E3: Baixa | F3: Aline Rocha | G3: Fechada | H3: 45659.603
A4: OS-1502 | B4: Disjuntor desarmando no painel G-09 | C4: Disjuntor do painel G-09 desarmou três vezes no turno. Carga dentro do nominal. | D4: Adutora Tronco Norte | E4: Média | F4: Flávio Gusmão | G4: Fechada | H4: 45659.914
A5: OS-1503 | B5: Troca de filtro do compressor E-15 | C5: Filtro de ar do compressor E-15 saturado. Substituição preventiva. | D5: Laboratório de Controle | E5: Média | F5: Juliana Aguiar | G5: Fechada | H5: 45660.207
A6: OS-1504 | B6: Ruído anormal no motor A-08 | C6: Ruído intermitente no motor A-08 durante a partida. Temperatura normal ao toque. | D6: ETA Serra Azul | E6: Crítica | F6: Érica Andrade | G6: Fechada | H6: 45660.542
A7: OS-1505 | B7: Infiltração na parede da casa de bombas A-32 | C7: Mancha de umidade crescente na parede da casa de bombas A-32. | D7: Subestação Norte | E7: Baixa | F7: Alex Nogueira | G7: Fechada | H7: 45660.831
A8: OS-1506 | B8: Disjuntor desarmando no painel G-14 | C8: Disjuntor do painel G-14 desarmou três vezes no turno. Carga dentro do nominal. | D8: Base Operacional Sul | E8: Média | F8: Gabriel Matos | G8: Fechada | H8: 45661.153
A9: OS-1507 | B9: Disjuntor desarmando no painel M-09 | C9: Disjuntor do painel M-09 desarmou três vezes no turno. Carga dentro do nominal. | D9: Base Operacional Norte | E9: Alta | F9: Flávio Gusmão | G9: Fechada | H9: 45661.427
A10: OS-1508 | B10: Lâmpada queimada na área F-21 | C10: Iluminação da área F-21 sem funcionar. Reposição de lâmpada e conferência do reator. | D10: Booster Morada do Sol | E10: Baixa | F10: Thiago Bastos | G10: Fechada | H10: 45661.739
A11: OS-1509 | B11: Ruído anormal no motor F-24 | C11: Ruído intermitente no motor F-24 durante a partida. Temperatura normal ao toque. | D11: ETE Rio Claro | E11: Média | F11: Priscila Guedes | G11: Fechada | H11: 45662.062
A12: OS-1510 | B12: Aquecimento no mancal do motor E-06 | C12: Mancal do motor E-06 acima da temperatura usual na medição com termômetro infravermelho. | D12: Estação Elevatória Oeste | E12: Média | F12: Beatriz Farias | G12: Fechada | H12: 45662.371
A13: OS-1511 | B13: Lâmpada queimada na área H-18 | C13: Iluminação da área H-18 sem funcionar. Reposição de lâmpada e conferência do reator. | D13: Captação Rio Verde | E13: Crítica | F13: Murilo Paiva | G13: Fechada | H13: 45662.647
... A1181: OS-2679 | B1181: Medidor de vazão E-30 com leitura instável | C1181: Medidor de vazão E-30 oscila sem variação de processo. | D1181: Galpão de Materiais | E1181: Baixa | F1181: Aline Rocha | G1181: Fechada | H1181: 46019.014
